Workbook

Sheet Assumptions
A1: Market size | B1: 250000 | D1: User base
A2: Penetration year 1 | B2: 0.003 | D2: =B1*B2 -> 750
A3: Penetration year 2 | B3: 0.01 | D3: =B1*B3 -> 2500
A4: Penetration year 3 | B4: 0.025 | D4: =B1*B4 -> 6250
A6: Average order quantity per customer' per month | B6: 20
A7: Average order value per meal | B7: 18
A8: Commision (listing fee, convineance fee)
A10: year 1 | B10: 0.15
A11: year 2 | B11: 0.16
A12: year 3 | B12: 0.18
A14: Monthly customer growth rate | B14: 0.08
A16: Fixed costs:

Sheet Revenue
A1: Customers acquired:
A3: Year 1
B4: No. of customers | C4: Growth rate | D4: No. of orders | E4: GMV | F4: Revenue
A5: Jan | B5: 300 | C5: - | D5: =B5*20 -> 6000 | E5: =D5*18 -> 108000 | F5: =E5*15%+5/20*D5 -> 17700
A6: Feb | B6: =B5*(1+C6) -> 309 | C6: 0.03 | D6: =B6*20 -> 6180 | E6: =D6*18 -> 111240 | F6: =E6*15%+5/20*D6 -> 18231
A7: Mar | B7: =B6*(1+C7) -> 318.27 | C7: 0.03 | D7: =B7*20 -> 6365.4 | E7: =D7*18 -> 114577.2 | F7: =E7*15%+5/20*D7 -> 18777.93
A8: Apr | B8: =B7*(1+C8) -> 327.8181 | C8: 0.03 | D8: =B8*20 -> 6556.362 | E8: =D8*18 -> 118014.52 | F8: =E8*15%+5/20*D8 -> 19341.268
A9: May | B9: =B8*(1+C9) -> 337.65264 | C9: 0.03 | D9: =B9*20 -> 6753.0529 | E9: =D9*18 -> 121554.95 | F9: =E9*15%+5/20*D9 -> 19921.506 | I9: =(415-300)/300 -> 0.38333333
A10: Jun | B10: =B9*(1+C10) -> 347.78222 | C10: 0.03 | D10: =B10*20 -> 6955.6444 | E10: =D10*18 -> 125201.6 | F10: =E10*15%+5/20*D10 -> 20519.151
A11: Jul | B11: =B10*(1+C11) -> 358.21569 | C11: 0.03 | D11: =B11*20 -> 7164.3138 | E11: =D11*18 -> 128957.65 | F11: =E11*15%+5/20*D11 -> 21134.726
A12: Aug | B12: =B11*(1+C12) -> 368.96216 | C12: 0.03 | D12: =B12*20 -> 7379.2432 | E12: =D12*18 -> 132826.38 | F12: =E12*15%+5/20*D12 -> 21768.767
A13: Sep | B13: =B12*(1+C13) -> 380.03102 | C13: 0.03 | D13: =B13*20 -> 7600.6205 | E13: =D13*18 -> 136811.17 | F13: =E13*15%+5/20*D13 -> 22421.83
A14: Oct | B14: =B13*(1+C14) -> 391.43196 | C14: 0.03 | D14: =B14*20 -> 7828.6391 | E14: =D14*18 -> 140915.5 | F14: =E14*15%+5/20*D14 -> 23094.485
A15: Nov | B15: =B14*(1+C15) -> 403.17491 | C15: 0.03 | D15: =B15*20 -> 8063.4983 | E15: =D15*18 -> 145142.97 | F15: =E15*15%+5/20*D15 -> 23787.32
A16: Dec | B16: =B15*(1+C16) -> 415.27016 | C16: 0.03 | D16: =B16*20 -> 8305.4032 | E16: =D16*18 -> 149497.26 | F16: =E16*15%+5/20*D16 -> 24500.94
A18: Total | B18: =SUM(B5:B16) -> 4257.6089 | D18: =SUM(D5:D16) -> 85152.177 | E18: =SUM(E5:E16) -> 1532739.2 | F18: =SUM(F5:F16) -> 251198.92
A21: Year 2 | B21: No. of customers | C21: Growth rate | D21: No. of orders | E21: GMV | F21: Revenue
A23: Jan | B23: =B16*(1+C23) -> 436.03367 | C23: 0.05 | D23: =B23*20 -> 8720.6734 | E23: =D23*18.648 -> 162623.12 | F23: =E23*17%+5/20*D23 -> 29826.098
A24: Feb | B24: =B23*(1+C24) -> 457.83535 | C24: 0.05 | D24: =B24*20 -> 9156.7071 | E24: =D24*18.648 -> 170754.27 | F24: =E24*17%+5/20*D24 -> 31317.403
A25: Mar | B25: =B24*(1+C25) -> 480.72712 | C25: 0.05 | D25: =B25*20 -> 9614.5424 | E25: =D25*18.648 -> 179291.99 | F25: =E25*17%+5/20*D25 -> 32883.273
A26: Apr | B26: =B25*(1+C26) -> 504.76348 | C26: 0.05 | D26: =B26*20 -> 10095.27 | E26: =D26*18.648 -> 188256.59 | F26: =E26*17%+5/20*D26 -> 34527.437
A27: May | B27: =B26*(1+C27) -> 530.00165 | C27: 0.05 | D27: =B27*20 -> 10600.033 | E27: =D27*18.648 -> 197669.42 | F27: =E27*17%+5/20*D27 -> 36253.809
A28: Jun | B28: =B27*(1+C28) -> 556.50173 | C28: 0.05 | D28: =B28*20 -> 11130.035 | E28: =D28*18.648 -> 207552.89 | F28: =E28*17%+5/20*D28 -> 38066.499
A29: Jul | B29: =B28*(1+C29) -> 584.32682 | C29: 0.05 | D29: =B29*20 -> 11686.536 | E29: =D29*18.648 -> 217930.53 | F29: =E29*17%+5/20*D29 -> 39969.824
A30: Aug | B30: =B29*(1+C30) -> 613.54316 | C30: 0.05 | D30: =B30*20 -> 12270.863 | E30: =D30*18.648 -> 228827.06 | F30: =E30*17%+5/20*D30 -> 41968.316
A31: Sep | B31: =B30*(1+C31) -> 644.22032 | C31: 0.05 | D31: =B31*20 -> 12884.406 | E31: =D31*18.648 -> 240268.41 | F31: =E31*17%+5/20*D31 -> 44066.731
A32: Oct | B32: =B31*(1+C32) -> 676.43133 | C32: 0.05 | D32: =B32*20 -> 13528.627 | E32: =D32*18.648 -> 252281.83 | F32: =E32*17%+5/20*D32 -> 46270.068
A33: Nov | B33: =B32*(1+C33) -> 710.2529 | C33: 0.05 | D33: =B33*20 -> 14205.058 | E33: =D33*18.648 -> 264895.92 | F33: =E33*17%+5/20*D33 -> 48583.571
A34: Dec | B34: =B33*(1+C34) -> 745.76555 | C34: 0.05 | D34: =B34*20 -> 14915.311 | E34: =D34*18.648 -> 278140.72 | F34: =E34*17%+5/20*D34 -> 51012.75
A36: Total | B36: =SUM(B23:B34) -> 6940.4031 | D36: =SUM(D23:D34) -> 138808.06 | E36: =SUM(E23:E34) -> 2588492.7 | F36: =SUM(F23:F34) -> 474745.78
A39: Year 3 | B39: No. of customers | C39: Growth rate | D39: No. of orders | E39: GMV | F39: Revenue
A41: Jan | B41: =B34*(1+C41) -> 797.96913 | C41: 0.07 | D41: =B41*20 -> 15959.383 | E41: =D41*(19.319) -> 308319.31 | F41: =E41*18%+D41*5/20 -> 59487.322
A42: Feb | B42: =B41*(1+C42) -> 853.82697 | C42: 0.07 | D42: =B42*20 -> 17076.539 | E42: =D42*(19.319) -> 329901.67 | F42: =E42*18%+D42*5/20 -> 63651.435
A43: Mar | B43: =B42*(1+C43) -> 913.59486 | C43: 0.07 | D43: =B43*20 -> 18271.897 | E43: =D43*(19.319) -> 352994.78 | F43: =E43*18%+D43*5/20 -> 68107.035
A44: Apr | B44: =B43*(1+C44) -> 977.5465 | C44: 0.07 | D44: =B44*20 -> 19550.93 | E44: =D44*(19.319) -> 377704.42 | F44: =E44*18%+D44*5/20 -> 72874.528
A45: May | B45: =B44*(1+C45) -> 1045.9748 | C45: 0.07 | D45: =B45*20 -> 20919.495 | E45: =D45*(19.319) -> 404143.73 | F45: =E45*18%+D45*5/20 -> 77975.745
A46: Jun | B46: =B45*(1+C46) -> 1119.193 | C46: 0.07 | D46: =B46*20 -> 22383.86 | E46: =D46*(19.319) -> 432433.79 | F46: =E46*18%+D46*5/20 -> 83434.047
A47: Jul | B47: =B46*(1+C47) -> 1197.5365 | C47: 0.07 | D47: =B47*20 -> 23950.73 | E47: =D47*(19.319) -> 462704.15 | F47: =E47*18%+D47*5/20 -> 89274.43
A48: Aug | B48: =B47*(1+C48) -> 1281.3641 | C48: 0.07 | D48: =B48*20 -> 25627.281 | E48: =D48*(19.319) -> 495093.44 | F48: =E48*18%+D48*5/20 -> 95523.64
A49: Sep | B49: =B48*(1+C49) -> 1371.0595 | C49: 0.07 | D49: =B49*20 -> 27421.191 | E49: =D49*(19.319) -> 529749.98 | F49: =E49*18%+D49*5/20 -> 102210.29
...

Sheet Cost
A1: One time costs (upfront)
A3: App development (all in) | B3: 10000
A5: Legal
A7: Item | B7: Cost (AED)
A8: Freezone license (IFZA/SHAMS/RAKEZ) | B8: 12000
A9: E-commerce activity fee | B9: 1500
A10: Establishment card | B10: 1000
A11: Basic legal documentation | B11: 1000
A12: Bank minimum balance | B12: 5000
A13: Total | B13: =SUM(B8:B12) -> 20500
A15: Launch creatives, promo videos | B15: 2000
A17: Total upfront cost | B17: =SUM(B3,B13,B15) -> 32500
A20: Fixed costs
A22: Technical costs
A24: Item | B24: Monthly Cost (AED)
A25: Cloud hosting (AWS / Render / DigitalOcean) | B25: 250
A26: Managed database | B26: 159
A27: File storage (images) | B27: 70
A28: API costs (Maps, routing, geocoding) | B28: 159
A29: Email + OTP + notifications | B29: 100
A31: Total technical costs | B31: =SUM(B25:B29) -> 738
A33: Operational costs
A35: Role | B35: Monthly Cost (AED) | C35: Notes
A36: Part-time operations coordinator | B36: 2000 | C36: Founder-led + one helper.
A37: Freelance dev retainer | B37: 3000 | C37: For bug fixes & feature additions.
A39: Total operational costs | B39: 5000
A41: Marketing budget
A43: Channel | B43: Monthly Spend (AED)
A44: Instagram/TikTok ads | B44: 1500
A45: Influencers (micro) | B45: 600
A46: University stalls (occasional) | B46: 600
A47: Free food tasting subsidized by vendors | B47: 0
A48: New idea budget (small events/promo) | B48: 1000
A50: Total marketing costs | B50: =SUM(B44:B48) -> 3700
A52: Admin and misc
A54: Item | B54: Monthly Cost (AED)
A55: Accounting (freelancer) | B55: 300
A56: Domain + hosting | B56: 50
A57: Co-working (hot desk) | B57: 500
A58: Misc | B58: 500
...

Sheet Unit economics
A2: Monthly orders | B2: Order value | C2: Commision | D2: Revenue per customer
A3: 20 | B3: 18 | C3: 0.15 | D3: =A3*B3*C3+5/30 -> 54.166667
A5: Payment gateway cost | D5: =B3*2.5%+0.5 -> 0.95
A6: Customer support load | D6: 0.2
A7: Refund buffer | D7: 0.15
A8: Infra | D8: 0.002
A10: Revenue per order | C10: =B3*C3 -> 2.7
A11: Variable cost per order | C11: =SUM(D5:D8) -> 1.302
A12: Contribution | C12: =C10-C11 -> 1.398
A14: Contribution per customer | C14: =A3*C12 -> 27.96 | D14: (per month)

Sheet Break even analysis
A1: Total upfront cost (month zero) | B1: =-Cost!B17 -> -32500
A3: Contribution per customer | B3: ='Unit economics'!C14 -> 27.96 | C3: (per month)
A4: Expected fixed cost | B4: =Cost!B62 -> 10788 | C4: (per month)
A6: Month | B6: Net profit | C6: Net cash
A7: 0 | B7: 0 | C7: =B1 -> -32500
A8: 1 | B8: =$B$3*Revenue!B5-$B$4 -> -2400 | C8: =C7+B8 -> -34900
A9: 2 | B9: =$B$3*Revenue!B6-$B$4 -> -2148.36 | C9: =C8+B9 -> -37048.36
A10: 3 | B10: =$B$3*Revenue!B7-$B$4 -> -1889.1708 | C10: =C9+B10 -> -38937.531
A11: 4 | B11: =$B$3*Revenue!B8-$B$4 -> -1622.2059 | C11: =C10+B11 -> -40559.737
A12: 5 | B12: =$B$3*Revenue!B9-$B$4 -> -1347.2321 | C12: =C11+B12 -> -41906.969
A13: 6 | B13: =$B$3*Revenue!B10-$B$4 -> -1064.0091 | C13: =C12+B13 -> -42970.978
A14: 7 | B14: =$B$3*Revenue!B11-$B$4 -> -772.28934 | C14: =C13+B14 -> -43743.267
A15: 8 | B15: =$B$3*Revenue!B12-$B$4 -> -471.81802 | C15: =C14+B15 -> -44215.085
A16: 9 | B16: =$B$3*Revenue!B13-$B$4 -> -162.33256 | C16: =C15+B16 -> -44377.418
A17: 10 | B17: =$B$3*Revenue!B14-$B$4 -> 156.43747 | C17: =C16+B17 -> -44220.98
A18: 11 | B18: =$B$3*Revenue!B15-$B$4 -> 484.77059 | C18: =C17+B18 -> -43736.21
A19: 12 | B19: =$B$3*Revenue!B16-$B$4 -> 822.95371 | C19: =C18+B19 -> -42913.256
A20: 13 | B20: =$B$3*Revenue!B23-'Break even analysis'!$B$4 -> 1403.5014 | C20: =C19+B20 -> -41509.755
A21: 14 | B21: =$B$3*Revenue!B24-'Break even analysis'!$B$4 -> 2013.0765 | C21: =C20+B21 -> -39496.678
A22: 15 | B22: =$B$3*Revenue!B25-'Break even analysis'!$B$4 -> 2653.1303 | C22: =C21+B22 -> -36843.548
A23: 16 | B23: =$B$3*Revenue!B26-'Break even analysis'!$B$4 -> 3325.1868 | C23: =C22+B23 -> -33518.361
A24: 17 | B24: =$B$3*Revenue!B27-'Break even analysis'!$B$4 -> 4030.8461 | C24: =C23+B24 -> -29487.515
A25: 18 | B25: =$B$3*Revenue!B28-'Break even analysis'!$B$4 -> 4771.7884 | C25: =C24+B25 -> -24715.727
A26: 19 | B26: =$B$3*Revenue!B29-'Break even analysis'!$B$4 -> 5549.7779 | C26: =C25+B26 -> -19165.949
A27: 20 | B27: =$B$3*Revenue!B30-'Break even analysis'!$B$4 -> 6366.6668 | C27: =C26+B27 -> -12799.282
A28: 21 | B28: =$B$3*Revenue!B31-'Break even analysis'!$B$4 -> 7224.4001 | C28: =C27+B28 -> -5574.8818
A29: 22 | B29: =$B$3*Revenue!B32-'Break even analysis'!$B$4 -> 8125.0201 | C29: =C28+B29 -> 2550.1383
A30: 23 | B30: =$B$3*Revenue!B33-'Break even analysis'!$B$4 -> 9070.6711 | C30: =C29+B30 -> 11620.809
A31: 24 | B31: =$B$3*Revenue!B34-'Break even analysis'!$B$4 -> 10063.605 | C31: =C30+B31 -> 21684.414
A32: 25 | B32: =$B$3*Revenue!B41-'Break even analysis'!$B$4 -> 11523.217 | C32: =C31+B32 -> 33207.631
A33: 26 | B33: =$B$3*Revenue!B42-'Break even analysis'!$B$4 -> 13085.002 | C33: =C32+B33 -> 46292.633
A34: 27 | B34: =$B$3*Revenue!B43-'Break even analysis'!$B$4 -> 14756.112 | C34: =C33+B34 -> 61048.746
A35: 28 | B35: =$B$3*Revenue!B44-'Break even analysis'!$B$4 -> 16544.2 | C35: =C34+B35 -> 77592.946
A36: 29 | B36: =$B$3*Revenue!B45-'Break even analysis'!$B$4 -> 18457.454 | C36: =C35+B36 -> 96050.4
A37: 30 | B37: =$B$3*Revenue!B46-'Break even analysis'!$B$4 -> 20504.636 | C37: =C36+B37 -> 116555.04
A38: 31 | B38: =$B$3*Revenue!B47-'Break even analysis'!$B$4 -> 22695.121 | C38: =C37+B38 -> 139250.16
A39: 32 | B39: =$B$3*Revenue!B48-'Break even analysis'!$B$4 -> 25038.939 | C39: =C38+B39 -> 164289.1
A40: 33 | B40: =$B$3*Revenue!B49-'Break even analysis'!$B$4 -> 27546.825 | C40: =C39+B40 -> 191835.92
A41: 34 | B41: =$B$3*Revenue!B50-'Break even analysis'!$B$4 -> 30230.262 | C41: =C40+B41 -> 222066.18
A42: 35 | B42: =$B$3*Revenue!B51-'Break even analysis'!$B$4 -> 33101.541 | C42: =C41+B42 -> 255167.72
...

Sheet Projected P&L
A1: Year | B1: 1 | C1: 2 | D1: 3
A3: Revenue | B3: =Revenue!F18 -> 251198.92 | C3: =Revenue!F36 -> 474745.78 | D3: =Revenue!F54 -> 1064136.1
A4: Technical costs | B4: =Cost!B31 -> 738 | C4: =B4*1.1 -> 811.8 | D4: =C4*1.1 -> 892.98
A5: Operational costs | B5: =Cost!B39 -> 5000 | C5: =B5*1.1 -> 5500 | D5: =C5*1.1 -> 6050
A6: Marketing costs | B6: =Cost!B50 -> 3700 | C6: =B6*1.1 -> 4070 | D6: =C6*1.1 -> 4477
A7: Admin and misc | B7: =Cost!B60 -> 1350 | C7: =B7*1.1 -> 1485 | D7: =C7*1.1 -> 1633.5
A8: Total fixed costs | B8: =SUM(B4:B7) -> 10788 | C8: =SUM(C4:C7) -> 11866.8 | D8: =SUM(D4:D7) -> 13053.48
A9: Payment gateway costs | B9: =Revenue!E18*2.5%+Revenue!D18*0.5 -> 80894.569 | C9: =Revenue!E36*2.5%+Revenue!D36*0.5 -> 134116.35 | D9: =Revenue!E54*2.5%+Revenue!D54*0.5 -> 280628.2
A10: Customer support load | B10: =Revenue!D18*0.2 -> 17030.435 | C10: =0.2*Revenue!D36 -> 27761.612 | D10: =0.2*Revenue!D54 -> 57097.728
A11: Refund and quality issues | B11: =Revenue!E18*0.02 -> 30654.784 | C11: =Revenue!E36*0.02 -> 51769.855 | D11: =Revenue!E54*0.02 -> 110307.1
A12: Total variable cost | B12: =SUM(B9:B11) -> 128579.79 | C12: =SUM(C9:C11) -> 213647.82 | D12: =SUM(D9:D11) -> 448033.02
A13: EBIT | B13: =B3-B8-B12 -> 111831.14 | C13: =C3-C8-C12 -> 249231.16 | D13: =D3-D8-D12 -> 603049.56
